<?xml version="1.0"?>

<robot xmlns:xacro="http://www.ros.org/wiki/xacro" name="realsense_explorer">

  <xacro:arg name="use_nominal_extrinsics" default="false"/>
  <xacro:arg name="add_plug" default="false" />
  <xacro:arg name="use_mesh" default="true" />

  <xacro:include filename="$(find realsense_explorer_description)/urdf/realsense_bot.urdf.xacro" />

  <material name="invisible">
    <color rgba="0 0 0 0"/>
  </material>

  <material name="green">
    <color rgba="0 1 0 1"/>
  </material>

  <material name="grey">
    <color rgba="0.9 0.9 0.9 1"/>
  </material>


<link name="base_footprint"/>


  <link name="robot_base">
    <visual>
      <origin rpy="1.57 0 3.14" xyz="0.15 -0.117 0"/>
      <geometry>
        <mesh scale="0.001 0.001 0.001" filename="package://realsense_explorer_description/meshes/robot_chassis.STL"/>
      </geometry>
      <material name="grey"/>
    </visual>
  
      <collision>
      <origin rpy="1.57 0 3.14" xyz="0.15 -0.117 0"/>
      <geometry>
        <mesh scale="0.001 0.001 0.001" filename="package://realsense_explorer_description/meshes/robot_chassis.STL"/>
      </geometry>
    </collision>

  </link>

    <joint name="base_joint" type="fixed">
      <origin rpy="0 0 0" xyz="0 0 0" />
      <parent link="base_footprint"/>
      <child link="robot_base" />
    </joint>

  <joint name="chasis_to_rbot" type="fixed">
    <parent link="robot_base"/>
    <child link="rbot_base"/>
    <origin xyz="-0.09 0 0.13787" rpy="0 0 0"/>
  </joint>



<link name="link_right_wheel">        
        
  <collision name="link_right_wheel_visual">      
    <origin rpy="0 1.5707 1.57" xyz="0 0 0"/>      
    <geometry>        
      <cylinder length="0.04" radius="0.055"/>    
    </geometry>         
  </collision>      
       
  <visual name="link_right_wheel_visual">      
    <origin rpy="0 1.5707 1.57" xyz="0 0 0"/>      
    <geometry>        
      <cylinder length="0.04" radius="0.055"/>    
    </geometry>
    <material name="invisible"/>         
  </visual>      
</link>

<joint name="joint_right_wheel" type="continuous">    
  <origin rpy="0 0 0" xyz="0 -0.1 0.055"/>    
  <child link="link_right_wheel" />    
  <parent link="robot_base"/>    
  <axis rpy="0 0 0" xyz="0 1 0"/>    
  <limit effort="10000" velocity="1000"/>    
  <joint_properties damping="1.0" friction="1.0" />  
</joint>

<link name="link_left_wheel">        
        
  <collision name="link_left_wheel_visual">      
    <origin rpy="0 1.5707 1.57" xyz="0 0 0"/>      
    <geometry>        
      <cylinder length="0.04" radius="0.055"/>    
    </geometry>         
  </collision>      
       
  <visual name="link_left_wheel_visual">      
    <origin rpy="0 1.5707 1.57" xyz="0 0 0"/>      
    <geometry>        
      <cylinder length="0.04" radius="0.055"/>    
    </geometry>       
    <material name="invisible"/>  
  </visual>      
</link>

<joint name="joint_left_wheel" type="continuous">    
  <origin rpy="0 0 0" xyz="0 0.1 0.055"/>    
  <child link="link_left_wheel" />    
  <parent link="robot_base"/>    
  <axis rpy="0 0 0" xyz="0 1 0"/>    
  <limit effort="10000" velocity="1000"/>    
  <joint_properties damping="1.0" friction="1.0" />  
</joint>

  <link name="imu_link">
    <visual>
      <geometry>
        <box size="0.015 0.026 0.001"/>
      </geometry>
      <material name="green"/>
    </visual>
  </link>

<joint name="imu_joint" type="fixed">    
  <origin rpy="0 0 0" xyz="0.114 0 0.05"/>    
  <child link="imu_link" />    
  <parent link="robot_base"/>    
</joint>


<transmission name="right_wheel_transmission">
  <type>transmission_interface/SimpleTransmission</type>
    
  <joint name="joint_right_wheel">
    <hardwareInterface>
      hardware_interface/VelocityJointInterface
    </hardwareInterface>      
  </joint> 
   
  <actuator name="right_wheel_actuator">        
    <mechanicalReduction>1</mechanicalReduction>    
    <hardwareInterface>
      VelocityJointInterface
    </hardwareInterface>   
  </actuator> 
 
</transmission>

<transmission name="left_wheel_transmission">
  <type>transmission_interface/SimpleTransmission</type>
    
  <joint name="joint_left_wheel">
    <hardwareInterface>
      hardware_interface/VelocityJointInterface
    </hardwareInterface>      
  </joint> 
   
  <actuator name="left_wheel_actuator">        
    <mechanicalReduction>1</mechanicalReduction>    
    <hardwareInterface>
      VelocityJointInterface
    </hardwareInterface>   
  </actuator> 
 
</transmission>





</robot>